# type: ignore
# NOASYNCIO
# asyncio has different mechanisms for shielded scopes, so would raise additional errors in this file.
from contextlib import asynccontextmanager

import trio


async def foo():
    try:
        ...
    finally:
        with trio.move_on_after(deadline=30) as s:
            s.shield = True
            await foo()

    try:
        pass
    finally:
        with trio.move_on_after(30) as s:
            s.shield = True
            await foo()

    try:
        pass
    finally:
        await foo()  # error: 8, Statement("try/finally", lineno-3)

    try:
        pass
    finally:
        with trio.move_on_after(30) as s:
            await foo()  # error: 12, Statement("try/finally", lineno-4)

    try:
        pass
    finally:
        with trio.move_on_after(30):
            await foo()  # error: 12, Statement("try/finally", lineno-4)

    bar = 10

    try:
        pass
    finally:
        with trio.move_on_after(bar) as s:
            s.shield = True
            await foo()

    try:
        pass
    finally:
        with trio.move_on_after(bar) as s:
            s.shield = False
            s.shield = True
            await foo()

    try:
        pass
    finally:
        with trio.move_on_after(bar) as s:
            s.shield = True
            await foo()
            s.shield = False
            await foo()  # error: 12, Statement("try/finally", lineno-7)
            s.shield = True
            await foo()

    try:
        pass
    finally:
        with open("bar"):
            await foo()  # error: 12, Statement("try/finally", lineno-4)
    try:
        pass
    finally:
        with open("bar"):
            pass
    try:
        pass
    finally:
        with trio.move_on_after():
            await foo()  # error: 12, Statement("try/finally", lineno-4)
    try:
        pass
    finally:
        with trio.move_on_after(foo=bar):
            await foo()  # error: 12, Statement("try/finally", lineno-4)
    try:
        pass
    finally:
        with trio.CancelScope(deadline=30, shield=True):
            await foo()  # safe
    try:
        pass
    finally:
        with trio.CancelScope(shield=True):
            await foo()  # error: 12, Statement("try/finally", lineno-4)
    try:
        pass
    finally:
        with trio.CancelScope(deadline=30):
            await foo()  # error: 12, Statement("try/finally", lineno-4)
    try:
        pass
    finally:
        with trio.CancelScope(deadline=30, shield=(1 == 1)):
            await foo()  # safe in theory, error: 12, Statement("try/finally", lineno-4)
    try:
        pass
    finally:
        myvar = True
        with trio.open_nursery(10) as s:
            s.shield = myvar
            await foo()  # safe in theory, error: 12, Statement("try/finally", lineno-6)
    try:
        pass
    finally:
        with trio.CancelScope(deadline=30, shield=True):
            with trio.move_on_after(30):
                await foo()  # safe
    try:
        pass
    finally:
        async for (  # error: 8, Statement("try/finally", lineno-3)
            i
        ) in trio.bypasslinters:
            pass
    try:
        pass
    finally:
        async with trio.CancelScope(  # error: 8, Statement("try/finally", lineno-3)
            deadline=30, shield=True
        ):
            await foo()  # safe

    with trio.CancelScope(deadline=30, shield=True):
        try:
            pass
        finally:
            await foo()  # error: 12, Statement("try/finally", lineno-3)


# change of functionality, no longer treated as safe
# https://github.com/python-trio/flake8-async/issues/54
@asynccontextmanager
async def foo2():
    try:
        yield 1
    finally:
        await foo()  # error: 8, Statement("try/finally", lineno-3)


async def foo3():
    try:
        ...
    finally:
        with trio.move_on_after(30) as s, trio.fail_after(5):
            s.shield = True
            await foo()  # safe
        with trio.move_on_after(30) as s, trio.fail_after(5):
            await foo()  # ASYNC102: 12, Statement("try/finally", lineno-7)
        with open(""), trio.CancelScope(deadline=30, shield=True):
            await foo()  # safe
        with trio.fail_after(5), trio.move_on_after(30) as s:
            s.shield = True
            await foo()  # safe in theory, error: 12, Statement("try/finally", lineno-12)


async def foo4():
    try:
        ...
    except ValueError:
        await foo()  # safe
    except BaseException:
        await foo()  # error: 8, Statement("BaseException", lineno-1)
    except:
        await foo()
        # safe, since BaseException will catch Cancelled
        # also fully redundant and will never be executed, but that's for another linter


async def foo5():
    try:
        ...
    except BaseException:
        with trio.CancelScope(deadline=30, shield=True):
            await foo()  # safe
    except:
        await foo()

    try:
        ...
    except:
        with trio.CancelScope(deadline=30, shield=True):
            await foo()  # safe


# Report errors in finally regardless of if cancelled is caught/not caught
async def foo_catch_finally():
    try:
        ...
    except BaseException:
        await foo()  # error: 8, Statement("BaseException", lineno-1)
    finally:
        await foo()  # error: 8, Statement("try/finally", lineno-5)

    try:
        ...
    except:
        await foo()  # error: 8, Statement("bare except", lineno-1)
    finally:
        await foo()  # error: 8, Statement("try/finally", lineno-5)

    try:
        ...
    finally:
        await foo()  # error: 8, Statement("try/finally", lineno-3)


# multiple errors on same line
# fmt: off
async def foo6():
    try:
        ...
    except BaseException:
        _ = await foo(), await foo()  # error: 12, Statement("BaseException", lineno-1) # error: 25, Statement("BaseException", lineno-1)
# fmt: on


# check that state management of `cancelled_caught` is handled correctly
async def foo_nested_excepts():
    await foo()
    try:
        await foo()
    except BaseException:
        await foo()  # error: 8, Statement("BaseException", lineno-1)
        try:
            await foo()  # error: 12, Statement("BaseException", lineno-3)
        except BaseException:
            await foo()  # error: 12, Statement("BaseException", lineno-1)
        except:
            # unsafe, because we're waiting inside the parent baseexception
            await foo()  # error: 12, Statement("BaseException", lineno-8)
        await foo()  # error: 8, Statement("BaseException", lineno-9)
    except:
        await foo()
        try:
            await foo()
        except BaseException:
            await foo()  # error: 12, Statement("BaseException", lineno-1)
        except:
            await foo()
        await foo()
    await foo()
